{"name": "test_two", "status": "failed", "statusDetails": {"message": "AssertionError: assert 5 in [1, 2, 3]", "trace": "self = <pyteststudy.allure.test_fix_class.Test_Fixture_Class object at 0x03F258C8>\n\n    @allure.story('测试用例2')\n    def test_two(self):\n        # 不调用fixture，也可以正常执行\n>       assert 5 in [1, 2, 3]\nE       assert 5 in [1, 2, 3]\n\ntest_fix_class.py:34: AssertionError"}, "start": 1594463580996, "stop": 1594463580997, "uuid": "18a9f5a2-659a-440b-8a04-b0bdc424d330", "historyId": "0ab539d698e8dc101f4c2a45e3d52168", "testCaseId": "0f49803589dcb015b78a7ac72e2d1168", "fullName": "test_fix_class.Test_Fixture_Class#test_two", "labels": [{"name": "feature", "value": "登录模块测试"}, {"name": "story", "value": "测试用例2"}, {"name": "suite", "value": "test_fix_class"}, {"name": "subSuite", "value": "Test_Fixture_Class"}, {"name": "host", "value": "LAPTOP-I8LM4QVS"}, {"name": "thread", "value": "5764-MainThread"}, {"name": "framework", "value": "pytest"}, {"name": "language", "value": "cpython3"}, {"name": "package", "value": "test_fix_class"}]}